Traceback (most recent call last):
  File "C:\Users\orect\mambaforge\envs\pyFin\Lib\site-packages\jupyter_cache\executors\utils.py", line 58, in single_nb_execution
    executenb(
  File "C:\Users\orect\mambaforge\envs\pyFin\Lib\site-packages\nbclient\client.py", line 1305, in execute
    return NotebookClient(nb=nb, resources=resources, km=km, **kwargs).execute()
           ^^^^^^^^^^^^^^^^^^^^^^^^^^^^^^^^^^^^^^^^^^^^^^^^^^^^^^^^^^^^^^^^^^^^^
  File "C:\Users\orect\mambaforge\envs\pyFin\Lib\site-packages\jupyter_core\utils\__init__.py", line 166, in wrapped
    return loop.run_until_complete(inner)
           ^^^^^^^^^^^^^^^^^^^^^^^^^^^^^^
  File "C:\Users\orect\mambaforge\envs\pyFin\Lib\asyncio\base_events.py", line 653, in run_until_complete
    return future.result()
           ^^^^^^^^^^^^^^^
  File "C:\Users\orect\mambaforge\envs\pyFin\Lib\site-packages\nbclient\client.py", line 705, in async_execute
    await self.async_execute_cell(
  File "C:\Users\orect\mambaforge\envs\pyFin\Lib\site-packages\nbclient\client.py", line 1058, in async_execute_cell
    await self._check_raise_for_error(cell, cell_index, exec_reply)
  File "C:\Users\orect\mambaforge\envs\pyFin\Lib\site-packages\nbclient\client.py", line 914, in _check_raise_for_error
    raise CellExecutionError.from_cell_and_msg(cell, exec_reply_content)
nbclient.exceptions.CellExecutionError: An error occurred while executing the following cell:
------------------
using Plots
plot(sin, -2π, 2π, label="sin(x)")
------------------


ArgumentError: Package Plots not found in current path.
- Run `import Pkg; Pkg.add("Plots")` to install the Plots package.

Stacktrace:
 [1] macro expansion
   @ .\loading.jl:1630 [inlined]
 [2] macro expansion
   @ .\lock.jl:267 [inlined]
 [3] require(into::Module, mod::Symbol)
   @ Base .\loading.jl:1611

