Traceback (most recent call last):
  File "C:\Users\orect\mambaforge\envs\pyFin\Lib\site-packages\jupyter_cache\executors\utils.py", line 58, in single_nb_execution
    executenb(
  File "C:\Users\orect\mambaforge\envs\pyFin\Lib\site-packages\nbclient\client.py", line 1305, in execute
    return NotebookClient(nb=nb, resources=resources, km=km, **kwargs).execute()
           ^^^^^^^^^^^^^^^^^^^^^^^^^^^^^^^^^^^^^^^^^^^^^^^^^^^^^^^^^^^^^^^^^^^^^
  File "C:\Users\orect\mambaforge\envs\pyFin\Lib\site-packages\jupyter_core\utils\__init__.py", line 166, in wrapped
    return loop.run_until_complete(inner)
           ^^^^^^^^^^^^^^^^^^^^^^^^^^^^^^
  File "C:\Users\orect\mambaforge\envs\pyFin\Lib\asyncio\base_events.py", line 653, in run_until_complete
    return future.result()
           ^^^^^^^^^^^^^^^
  File "C:\Users\orect\mambaforge\envs\pyFin\Lib\site-packages\nbclient\client.py", line 705, in async_execute
    await self.async_execute_cell(
  File "C:\Users\orect\mambaforge\envs\pyFin\Lib\site-packages\nbclient\client.py", line 1058, in async_execute_cell
    await self._check_raise_for_error(cell, cell_index, exec_reply)
  File "C:\Users\orect\mambaforge\envs\pyFin\Lib\site-packages\nbclient\client.py", line 914, in _check_raise_for_error
    raise CellExecutionError.from_cell_and_msg(cell, exec_reply_content)
nbclient.exceptions.CellExecutionError: An error occurred while executing the following cell:
------------------
# Nominal interest rate from https://fred.stlouisfed.org/series/GS1
# Real interest rate from https://fred.stlouisfed.org/series/WFII10
#
# Download as CSV files
#

using DataFrames, CSV, PyPlot

df_nominal = DataFrame(CSV.File("data/GS1.csv"))
df_real = DataFrame(CSV.File("data/WFII10.csv"))

function plot_rates(df; fontsize=16, savefig=true)
    r_type = df == df_nominal ? "nominal" : "real"
    fig, ax = plt.subplots(figsize=(9, 5))
    ax.plot(df[!, 1], df[!, 2], label=r_type*" interest rate")
    ax.plot(df[!, 1], zero(df[!, 2]), c="k", ls="--")
    ax.set_xlim(df[1, 1], df[end, 1])
    ax.legend(fontsize=fontsize, frameon=false)
    plt.show()
    if savefig
        fig.savefig("../figures/plot_interest_rates_"*r_type*".pdf")
    end
end

------------------


ArgumentError: Package DataFrames not found in current path.
- Run `import Pkg; Pkg.add("DataFrames")` to install the DataFrames package.

Stacktrace:
 [1] macro expansion
   @ .\loading.jl:1630 [inlined]
 [2] macro expansion
   @ .\lock.jl:267 [inlined]
 [3] require(into::Module, mod::Symbol)
   @ Base .\loading.jl:1611

